Workbook

Sheet Summary
A1: shift.mk / productivity
A2: TICKETS PER HOUR · QUOTAS · SET FROM / TO TO REPORT ANY DAY, WEEK OR MONTH
A3: FROM | B3: 46296
A4: TO | B4: 46326
A6: TICKETS | B6: PRODUCTIVE HRS | C6: TICKETS / HR | D6: LOGGED HRS | E6: DEDUCTED HRS | F6: SHIFT HRS
A7: =SUMIFS(Daily!$I:$I,Daily!$A:$A,">="&$B$3,Daily!$A:$A,"<="&$B$4) | B7: =SUMIFS(Daily!$H:$H,Daily!$A:$A,">="&$B$3,Daily!$A:$A,"<="&$B$4) | C7: =IF(B7>0,A7/B7,0) | D7: =SUMIFS(Daily!$F:$F,Daily!$A:$A,">="&$B$3,Daily!$A:$A,"<="&$B$4) | E7: =SUMIFS(Daily!$G:$G,Daily!$A:$A,">="&$B$3,Daily!$A:$A,"<="&$B$4) | F7: =SUMIFS(Daily!$K:$K,Daily!$A:$A,">="&$B$3,Daily!$A:$A,"<="&$B$4)
A9: tickets / hr = tickets ÷ productive hours, after deductions. Ranges sum the daily totals, so it is weighted by hours.
A11: TASKS VS QUOTA (PRODUCTIVE TAGS)
A12: TASK | B12: TICKETS | C12: HOURS | D12: T / HR | E12: QUOTA / H | F12: EXPECTED | G12: ATTAINMENT
A13: =IF(AND(Setup!$A$2<>"",Setup!$B$2="Y"),Setup!$A$2,"") | B13: =IF($A13="","",SUMIFS(Daily!$I:$I,Daily!$A:$A,">="&$B$3,Daily!$A:$A,"<="&$B$4,Daily!$C:$C,$A13)) | C13: =IF($A13="","",SUMIFS(Daily!$H:$H,Daily!$A:$A,">="&$B$3,Daily!$A:$A,"<="&$B$4,Daily!$C:$C,$A13)) | D13: =IF($A13="","",IF(C13>0,B13/C13,0)) | E13: =IF($A13="","",IF(N(Setup!$C$2)>0,Setup!$C$2,"")) | F13: =IF($A13="","",IF(AND(N(E13)>0,C13>0),E13*C13,"")) | G13: =IF($A13="","",IF(F13="","",B13/F13))
A14: =IF(AND(Setup!$A$3<>"",Setup!$B$3="Y"),Setup!$A$3,"") | B14: =IF($A14="","",SUMIFS(Daily!$I:$I,Daily!$A:$A,">="&$B$3,Daily!$A:$A,"<="&$B$4,Daily!$C:$C,$A14)) | C14: =IF($A14="","",SUMIFS(Daily!$H:$H,Daily!$A:$A,">="&$B$3,Daily!$A:$A,"<="&$B$4,Daily!$C:$C,$A14)) | D14: =IF($A14="","",IF(C14>0,B14/C14,0)) | E14: =IF($A14="","",IF(N(Setup!$C$3)>0,Setup!$C$3,"")) | F14: =IF($A14="","",IF(AND(N(E14)>0,C14>0),E14*C14,"")) | G14: =IF($A14="","",IF(F14="","",B14/F14))
A15: =IF(AND(Setup!$A$7<>"",Setup!$B$7="Y"),Setup!$A$7,"") | B15: =IF($A15="","",SUMIFS(Daily!$I:$I,Daily!$A:$A,">="&$B$3,Daily!$A:$A,"<="&$B$4,Daily!$C:$C,$A15)) | C15: =IF($A15="","",SUMIFS(Daily!$H:$H,Daily!$A:$A,">="&$B$3,Daily!$A:$A,"<="&$B$4,Daily!$C:$C,$A15)) | D15: =IF($A15="","",IF(C15>0,B15/C15,0)) | E15: =IF($A15="","",IF(N(Setup!$C$7)>0,Setup!$C$7,"")) | F15: =IF($A15="","",IF(AND(N(E15)>0,C15>0),E15*C15,"")) | G15: =IF($A15="","",IF(F15="","",B15/F15))
A16: =IF(AND(Setup!$A$8<>"",Setup!$B$8="Y"),Setup!$A$8,"") | B16: =IF($A16="","",SUMIFS(Daily!$I:$I,Daily!$A:$A,">="&$B$3,Daily!$A:$A,"<="&$B$4,Daily!$C:$C,$A16)) | C16: =IF($A16="","",SUMIFS(Daily!$H:$H,Daily!$A:$A,">="&$B$3,Daily!$A:$A,"<="&$B$4,Daily!$C:$C,$A16)) | D16: =IF($A16="","",IF(C16>0,B16/C16,0)) | E16: =IF($A16="","",IF(N(Setup!$C$8)>0,Setup!$C$8,"")) | F16: =IF($A16="","",IF(AND(N(E16)>0,C16>0),E16*C16,"")) | G16: =IF($A16="","",IF(F16="","",B16/F16))
A17: =IF(AND(Setup!$A$9<>"",Setup!$B$9="Y"),Setup!$A$9,"") | B17: =IF($A17="","",SUMIFS(Daily!$I:$I,Daily!$A:$A,">="&$B$3,Daily!$A:$A,"<="&$B$4,Daily!$C:$C,$A17)) | C17: =IF($A17="","",SUMIFS(Daily!$H:$H,Daily!$A:$A,">="&$B$3,Daily!$A:$A,"<="&$B$4,Daily!$C:$C,$A17)) | D17: =IF($A17="","",IF(C17>0,B17/C17,0)) | E17: =IF($A17="","",IF(N(Setup!$C$9)>0,Setup!$C$9,"")) | F17: =IF($A17="","",IF(AND(N(E17)>0,C17>0),E17*C17,"")) | G17: =IF($A17="","",IF(F17="","",B17/F17))
A18: =IF(AND(Setup!$A$10<>"",Setup!$B$10="Y"),Setup!$A$10,"") | B18: =IF($A18="","",SUMIFS(Daily!$I:$I,Daily!$A:$A,">="&$B$3,Daily!$A:$A,"<="&$B$4,Daily!$C:$C,$A18)) | C18: =IF($A18="","",SUMIFS(Daily!$H:$H,Daily!$A:$A,">="&$B$3,Daily!$A:$A,"<="&$B$4,Daily!$C:$C,$A18)) | D18: =IF($A18="","",IF(C18>0,B18/C18,0)) | E18: =IF($A18="","",IF(N(Setup!$C$10)>0,Setup!$C$10,"")) | F18: =IF($A18="","",IF(AND(N(E18)>0,C18>0),E18*C18,"")) | G18: =IF($A18="","",IF(F18="","",B18/F18))
A20: TIME BY TAG
A21: TAG | B21: HOURS | C21: % OF LOGGED
A22: =IF(Setup!$A$2="","",Setup!$A$2) | B22: =IF($A22="","",SUMIFS(Daily!$F:$F,Daily!$A:$A,">="&$B$3,Daily!$A:$A,"<="&$B$4,Daily!$C:$C,$A22)) | C22: =IF($A22="","",IF($D$7>0,B22/$D$7,0))
A23: =IF(Setup!$A$3="","",Setup!$A$3) | B23: =IF($A23="","",SUMIFS(Daily!$F:$F,Daily!$A:$A,">="&$B$3,Daily!$A:$A,"<="&$B$4,Daily!$C:$C,$A23)) | C23: =IF($A23="","",IF($D$7>0,B23/$D$7,0))
A24: =IF(Setup!$A$4="","",Setup!$A$4) | B24: =IF($A24="","",SUMIFS(Daily!$F:$F,Daily!$A:$A,">="&$B$3,Daily!$A:$A,"<="&$B$4,Daily!$C:$C,$A24)) | C24: =IF($A24="","",IF($D$7>0,B24/$D$7,0))
A25: =IF(Setup!$A$5="","",Setup!$A$5) | B25: =IF($A25="","",SUMIFS(Daily!$F:$F,Daily!$A:$A,">="&$B$3,Daily!$A:$A,"<="&$B$4,Daily!$C:$C,$A25)) | C25: =IF($A25="","",IF($D$7>0,B25/$D$7,0))
A26: =IF(Setup!$A$6="","",Setup!$A$6) | B26: =IF($A26="","",SUMIFS(Daily!$F:$F,Daily!$A:$A,">="&$B$3,Daily!$A:$A,"<="&$B$4,Daily!$C:$C,$A26)) | C26: =IF($A26="","",IF($D$7>0,B26/$D$7,0))
A27: =IF(Setup!$A$7="","",Setup!$A$7) | B27: =IF($A27="","",SUMIFS(Daily!$F:$F,Daily!$A:$A,">="&$B$3,Daily!$A:$A,"<="&$B$4,Daily!$C:$C,$A27)) | C27: =IF($A27="","",IF($D$7>0,B27/$D$7,0))
A28: =IF(Setup!$A$8="","",Setup!$A$8) | B28: =IF($A28="","",SUMIFS(Daily!$F:$F,Daily!$A:$A,">="&$B$3,Daily!$A:$A,"<="&$B$4,Daily!$C:$C,$A28)) | C28: =IF($A28="","",IF($D$7>0,B28/$D$7,0))
A29: =IF(Setup!$A$9="","",Setup!$A$9) | B29: =IF($A29="","",SUMIFS(Daily!$F:$F,Daily!$A:$A,">="&$B$3,Daily!$A:$A,"<="&$B$4,Daily!$C:$C,$A29)) | C29: =IF($A29="","",IF($D$7>0,B29/$D$7,0))
A30: =IF(Setup!$A$10="","",Setup!$A$10) | B30: =IF($A30="","",SUMIFS(Daily!$F:$F,Daily!$A:$A,">="&$B$3,Daily!$A:$A,"<="&$B$4,Daily!$C:$C,$A30)) | C30: =IF($A30="","",IF($D$7>0,B30/$D$7,0))

Sheet Daily
B1: 46296 | E1: shift 23:00 → 08:00 · 9.00 h · 18 intervals
B2: SLOT | C2: TAG | D2: TICKETS | E2: MINS | F2: HOURS | G2: DEDUCTED | H2: PROD HRS | I2: TICKETS | J2: T / HR
A3: 46296 | B3: 23:00–23:30 | F3: =IF($C3="","",IF($E3="",30,$E3)/60) | G3: =IF($C3="","",(30-IF($E3="",30,$E3))/60) | H3: =IF($C3="",0,IF(IFERROR(VLOOKUP($C3,Setup!$A$2:$B$60,2,FALSE),"N")="Y",$F3,0)) | I3: =IF($C3="",0,IF(IFERROR(VLOOKUP($C3,Setup!$A$2:$B$60,2,FALSE),"N")="Y",N($D3),0)) | J3: =IF($H3>0,$I3/$H3,"") | K3: =IF($F21>0,9,0)
A4: 46296 | B4: 23:30–00:00 | F4: =IF($C4="","",IF($E4="",30,$E4)/60) | G4: =IF($C4="","",(30-IF($E4="",30,$E4))/60) | H4: =IF($C4="",0,IF(IFERROR(VLOOKUP($C4,Setup!$A$2:$B$60,2,FALSE),"N")="Y",$F4,0)) | I4: =IF($C4="",0,IF(IFERROR(VLOOKUP($C4,Setup!$A$2:$B$60,2,FALSE),"N")="Y",N($D4),0)) | J4: =IF($H4>0,$I4/$H4,"")
A5: 46296 | B5: 00:00–00:30 | F5: =IF($C5="","",IF($E5="",30,$E5)/60) | G5: =IF($C5="","",(30-IF($E5="",30,$E5))/60) | H5: =IF($C5="",0,IF(IFERROR(VLOOKUP($C5,Setup!$A$2:$B$60,2,FALSE),"N")="Y",$F5,0)) | I5: =IF($C5="",0,IF(IFERROR(VLOOKUP($C5,Setup!$A$2:$B$60,2,FALSE),"N")="Y",N($D5),0)) | J5: =IF($H5>0,$I5/$H5,"")
A6: 46296 | B6: 00:30–01:00 | F6: =IF($C6="","",IF($E6="",30,$E6)/60) | G6: =IF($C6="","",(30-IF($E6="",30,$E6))/60) | H6: =IF($C6="",0,IF(IFERROR(VLOOKUP($C6,Setup!$A$2:$B$60,2,FALSE),"N")="Y",$F6,0)) | I6: =IF($C6="",0,IF(IFERROR(VLOOKUP($C6,Setup!$A$2:$B$60,2,FALSE),"N")="Y",N($D6),0)) | J6: =IF($H6>0,$I6/$H6,"")
A7: 46296 | B7: 01:00–01:30 | F7: =IF($C7="","",IF($E7="",30,$E7)/60) | G7: =IF($C7="","",(30-IF($E7="",30,$E7))/60) | H7: =IF($C7="",0,IF(IFERROR(VLOOKUP($C7,Setup!$A$2:$B$60,2,FALSE),"N")="Y",$F7,0)) | I7: =IF($C7="",0,IF(IFERROR(VLOOKUP($C7,Setup!$A$2:$B$60,2,FALSE),"N")="Y",N($D7),0)) | J7: =IF($H7>0,$I7/$H7,"")
A8: 46296 | B8: 01:30–02:00 | F8: =IF($C8="","",IF($E8="",30,$E8)/60) | G8: =IF($C8="","",(30-IF($E8="",30,$E8))/60) | H8: =IF($C8="",0,IF(IFERROR(VLOOKUP($C8,Setup!$A$2:$B$60,2,FALSE),"N")="Y",$F8,0)) | I8: =IF($C8="",0,IF(IFERROR(VLOOKUP($C8,Setup!$A$2:$B$60,2,FALSE),"N")="Y",N($D8),0)) | J8: =IF($H8>0,$I8/$H8,"")
A9: 46296 | B9: 02:00–02:30 | F9: =IF($C9="","",IF($E9="",30,$E9)/60) | G9: =IF($C9="","",(30-IF($E9="",30,$E9))/60) | H9: =IF($C9="",0,IF(IFERROR(VLOOKUP($C9,Setup!$A$2:$B$60,2,FALSE),"N")="Y",$F9,0)) | I9: =IF($C9="",0,IF(IFERROR(VLOOKUP($C9,Setup!$A$2:$B$60,2,FALSE),"N")="Y",N($D9),0)) | J9: =IF($H9>0,$I9/$H9,"")
A10: 46296 | B10: 02:30–03:00 | F10: =IF($C10="","",IF($E10="",30,$E10)/60) | G10: =IF($C10="","",(30-IF($E10="",30,$E10))/60) | H10: =IF($C10="",0,IF(IFERROR(VLOOKUP($C10,Setup!$A$2:$B$60,2,FALSE),"N")="Y",$F10,0)) | I10: =IF($C10="",0,IF(IFERROR(VLOOKUP($C10,Setup!$A$2:$B$60,2,FALSE),"N")="Y",N($D10),0)) | J10: =IF($H10>0,$I10/$H10,"")
A11: 46296 | B11: 03:00–03:30 | F11: =IF($C11="","",IF($E11="",30,$E11)/60) | G11: =IF($C11="","",(30-IF($E11="",30,$E11))/60) | H11: =IF($C11="",0,IF(IFERROR(VLOOKUP($C11,Setup!$A$2:$B$60,2,FALSE),"N")="Y",$F11,0)) | I11: =IF($C11="",0,IF(IFERROR(VLOOKUP($C11,Setup!$A$2:$B$60,2,FALSE),"N")="Y",N($D11),0)) | J11: =IF($H11>0,$I11/$H11,"")
A12: 46296 | B12: 03:30–04:00 | F12: =IF($C12="","",IF($E12="",30,$E12)/60) | G12: =IF($C12="","",(30-IF($E12="",30,$E12))/60) | H12: =IF($C12="",0,IF(IFERROR(VLOOKUP($C12,Setup!$A$2:$B$60,2,FALSE),"N")="Y",$F12,0)) | I12: =IF($C12="",0,IF(IFERROR(VLOOKUP($C12,Setup!$A$2:$B$60,2,FALSE),"N")="Y",N($D12),0)) | J12: =IF($H12>0,$I12/$H12,"")
A13: 46296 | B13: 04:00–04:30 | F13: =IF($C13="","",IF($E13="",30,$E13)/60) | G13: =IF($C13="","",(30-IF($E13="",30,$E13))/60) | H13: =IF($C13="",0,IF(IFERROR(VLOOKUP($C13,Setup!$A$2:$B$60,2,FALSE),"N")="Y",$F13,0)) | I13: =IF($C13="",0,IF(IFERROR(VLOOKUP($C13,Setup!$A$2:$B$60,2,FALSE),"N")="Y",N($D13),0)) | J13: =IF($H13>0,$I13/$H13,"")
A14: 46296 | B14: 04:30–05:00 | F14: =IF($C14="","",IF($E14="",30,$E14)/60) | G14: =IF($C14="","",(30-IF($E14="",30,$E14))/60) | H14: =IF($C14="",0,IF(IFERROR(VLOOKUP($C14,Setup!$A$2:$B$60,2,FALSE),"N")="Y",$F14,0)) | I14: =IF($C14="",0,IF(IFERROR(VLOOKUP($C14,Setup!$A$2:$B$60,2,FALSE),"N")="Y",N($D14),0)) | J14: =IF($H14>0,$I14/$H14,"")
A15: 46296 | B15: 05:00–05:30 | F15: =IF($C15="","",IF($E15="",30,$E15)/60) | G15: =IF($C15="","",(30-IF($E15="",30,$E15))/60) | H15: =IF($C15="",0,IF(IFERROR(VLOOKUP($C15,Setup!$A$2:$B$60,2,FALSE),"N")="Y",$F15,0)) | I15: =IF($C15="",0,IF(IFERROR(VLOOKUP($C15,Setup!$A$2:$B$60,2,FALSE),"N")="Y",N($D15),0)) | J15: =IF($H15>0,$I15/$H15,"")
... A20: 46296 | B20: 07:30–08:00 | F20: =IF($C20="","",IF($E20="",30,$E20)/60) | G20: =IF($C20="","",(30-IF($E20="",30,$E20))/60) | H20: =IF($C20="",0,IF(IFERROR(VLOOKUP($C20,Setup!$A$2:$B$60,2,FALSE),"N")="Y",$F20,0)) | I20: =IF($C20="",0,IF(IFERROR(VLOOKUP($C20,Setup!$A$2:$B$60,2,FALSE),"N")="Y",N($D20),0)) | J20: =IF($H20>0,$I20/$H20,"")
B21: TOTAL | D21: =SUM(I3:I20) | F21: =SUM(F3:F20) | G21: =SUM(G3:G20) | H21: =SUM(H3:H20) | J21: =IF(H21>0,D21/H21,"")
B23: 46297 | E23: shift 23:00 → 08:00 · 9.00 h · 18 intervals
B24: SLOT | C24: TAG | D24: TICKETS | E24: MINS | F24: HOURS | G24: DEDUCTED | H24: PROD HRS | I24: TICKETS | J24: T / HR
A25: 46297 | B25: 23:00–23:30 | F25: =IF($C25="","",IF($E25="",30,$E25)/60) | G25: =IF($C25="","",(30-IF($E25="",30,$E25))/60) | H25: =IF($C25="",0,IF(IFERROR(VLOOKUP($C25,Setup!$A$2:$B$60,2,FALSE),"N")="Y",$F25,0)) | I25: =IF($C25="",0,IF(IFERROR(VLOOKUP($C25,Setup!$A$2:$B$60,2,FALSE),"N")="Y",N($D25),0)) | J25: =IF($H25>0,$I25/$H25,"") | K25: =IF($F43>0,9,0)
A26: 46297 | B26: 23:30–00:00 | F26: =IF($C26="","",IF($E26="",30,$E26)/60) | G26: =IF($C26="","",(30-IF($E26="",30,$E26))/60) | H26: =IF($C26="",0,IF(IFERROR(VLOOKUP($C26,Setup!$A$2:$B$60,2,FALSE),"N")="Y",$F26,0)) | I26: =IF($C26="",0,IF(IFERROR(VLOOKUP($C26,Setup!$A$2:$B$60,2,FALSE),"N")="Y",N($D26),0)) | J26: =IF($H26>0,$I26/$H26,"")
A27: 46297 | B27: 00:00–00:30 | F27: =IF($C27="","",IF($E27="",30,$E27)/60) | G27: =IF($C27="","",(30-IF($E27="",30,$E27))/60) | H27: =IF($C27="",0,IF(IFERROR(VLOOKUP($C27,Setup!$A$2:$B$60,2,FALSE),"N")="Y",$F27,0)) | I27: =IF($C27="",0,IF(IFERROR(VLOOKUP($C27,Setup!$A$2:$B$60,2,FALSE),"N")="Y",N($D27),0)) | J27: =IF($H27>0,$I27/$H27,"")
A28: 46297 | B28: 00:30–01:00 | F28: =IF($C28="","",IF($E28="",30,$E28)/60) | G28: =IF($C28="","",(30-IF($E28="",30,$E28))/60) | H28: =IF($C28="",0,IF(IFERROR(VLOOKUP($C28,Setup!$A$2:$B$60,2,FALSE),"N")="Y",$F28,0)) | I28: =IF($C28="",0,IF(IFERROR(VLOOKUP($C28,Setup!$A$2:$B$60,2,FALSE),"N")="Y",N($D28),0)) | J28: =IF($H28>0,$I28/$H28,"")
A29: 46297 | B29: 01:00–01:30 | F29: =IF($C29="","",IF($E29="",30,$E29)/60) | G29: =IF($C29="","",(30-IF($E29="",30,$E29))/60) | H29: =IF($C29="",0,IF(IFERROR(VLOOKUP($C29,Setup!$A$2:$B$60,2,FALSE),"N")="Y",$F29,0)) | I29: =IF($C29="",0,IF(IFERROR(VLOOKUP($C29,Setup!$A$2:$B$60,2,FALSE),"N")="Y",N($D29),0)) | J29: =IF($H29>0,$I29/$H29,"")
A30: 46297 | B30: 01:30–02:00 | F30: =IF($C30="","",IF($E30="",30,$E30)/60) | G30: =IF($C30="","",(30-IF($E30="",30,$E30))/60) | H30: =IF($C30="",0,IF(IFERROR(VLOOKUP($C30,Setup!$A$2:$B$60,2,FALSE),"N")="Y",$F30,0)) | I30: =IF($C30="",0,IF(IFERROR(VLOOKUP($C30,Setup!$A$2:$B$60,2,FALSE),"N")="Y",N($D30),0)) | J30: =IF($H30>0,$I30/$H30,"")
A31: 46297 | B31: 02:00–02:30 | F31: =IF($C31="","",IF($E31="",30,$E31)/60) | G31: =IF($C31="","",(30-IF($E31="",30,$E31))/60) | H31: =IF($C31="",0,IF(IFERROR(VLOOKUP($C31,Setup!$A$2:$B$60,2,FALSE),"N")="Y",$F31,0)) | I31: =IF($C31="",0,IF(IFERROR(VLOOKUP($C31,Setup!$A$2:$B$60,2,FALSE),"N")="Y",N($D31),0)) | J31: =IF($H31>0,$I31/$H31,"")
A32: 46297 | B32: 02:30–03:00 | F32: =IF($C32="","",IF($E32="",30,$E32)/60) | G32: =IF($C32="","",(30-IF($E32="",30,$E32))/60) | H32: =IF($C32="",0,IF(IFERROR(VLOOKUP($C32,Setup!$A$2:$B$60,2,FALSE),"N")="Y",$F32,0)) | I32: =IF($C32="",0,IF(IFERROR(VLOOKUP($C32,Setup!$A$2:$B$60,2,FALSE),"N")="Y",N($D32),0)) | J32: =IF($H32>0,$I32/$H32,"")
A33: 46297 | B33: 03:00–03:30 | F33: =IF($C33="","",IF($E33="",30,$E33)/60) | G33: =IF($C33="","",(30-IF($E33="",30,$E33))/60) | H33: =IF($C33="",0,IF(IFERROR(VLOOKUP($C33,Setup!$A$2:$B$60,2,FALSE),"N")="Y",$F33,0)) | I33: =IF($C33="",0,IF(IFERROR(VLOOKUP($C33,Setup!$A$2:$B$60,2,FALSE),"N")="Y",N($D33),0)) | J33: =IF($H33>0,$I33/$H33,"")
A34: 46297 | B34: 03:30–04:00 | F34: =IF($C34="","",IF($E34="",30,$E34)/60) | G34: =IF($C34="","",(30-IF($E34="",30,$E34))/60) | H34: =IF($C34="",0,IF(IFERROR(VLOOKUP($C34,Setup!$A$2:$B$60,2,FALSE),"N")="Y",$F34,0)) | I34: =IF($C34="",0,IF(IFERROR(VLOOKUP($C34,Setup!$A$2:$B$60,2,FALSE),"N")="Y",N($D34),0)) | J34: =IF($H34>0,$I34/$H34,"")
A35: 46297 | B35: 04:00–04:30 | F35: =IF($C35="","",IF($E35="",30,$E35)/60) | G35: =IF($C35="","",(30-IF($E35="",30,$E35))/60) | H35: =IF($C35="",0,IF(IFERROR(VLOOKUP($C35,Setup!$A$2:$B$60,2,FALSE),"N")="Y",$F35,0)) | I35: =IF($C35="",0,IF(IFERROR(VLOOKUP($C35,Setup!$A$2:$B$60,2,FALSE),"N")="Y",N($D35),0)) | J35: =IF($H35>0,$I35/$H35,"")
A36: 46297 | B36: 04:30–05:00 | F36: =IF($C36="","",IF($E36="",30,$E36)/60) | G36: =IF($C36="","",(30-IF($E36="",30,$E36))/60) | H36: =IF($C36="",0,IF(IFERROR(VLOOKUP($C36,Setup!$A$2:$B$60,2,FALSE),"N")="Y",$F36,0)) | I36: =IF($C36="",0,IF(IFERROR(VLOOKUP($C36,Setup!$A$2:$B$60,2,FALSE),"N")="Y",N($D36),0)) | J36: =IF($H36>0,$I36/$H36,"")
A37: 46297 | B37: 05:00–05:30 | F37: =IF($C37="","",IF($E37="",30,$E37)/60) | G37: =IF($C37="","",(30-IF($E37="",30,$E37))/60) | H37: =IF($C37="",0,IF(IFERROR(VLOOKUP($C37,Setup!$A$2:$B$60,2,FALSE),"N")="Y",$F37,0)) | I37: =IF($C37="",0,IF(IFERROR(VLOOKUP($C37,Setup!$A$2:$B$60,2,FALSE),"N")="Y",N($D37),0)) | J37: =IF($H37>0,$I37/$H37,"")
... A42: 46297 | B42: 07:30–08:00 | F42: =IF($C42="","",IF($E42="",30,$E42)/60) | G42: =IF($C42="","",(30-IF($E42="",30,$E42))/60) | H42: =IF($C42="",0,IF(IFERROR(VLOOKUP($C42,Setup!$A$2:$B$60,2,FALSE),"N")="Y",$F42,0)) | I42: =IF($C42="",0,IF(IFERROR(VLOOKUP($C42,Setup!$A$2:$B$60,2,FALSE),"N")="Y",N($D42),0)) | J42: =IF($H42>0,$I42/$H42,"")
B43: TOTAL | D43: =SUM(I25:I42) | F43: =SUM(F25:F42) | G43: =SUM(G25:G42) | H43: =SUM(H25:H42) | J43: =IF(H43>0,D43/H43,"")
B45: 46298 | E45: shift 23:00 → 08:00 · 9.00 h · 18 intervals
B46: SLOT | C46: TAG | D46: TICKETS | E46: MINS | F46: HOURS | G46: DEDUCTED | H46: PROD HRS | I46: TICKETS | J46: T / HR
A47: 46298 | B47: 23:00–23:30 | F47: =IF($C47="","",IF($E47="",30,$E47)/60) | G47: =IF($C47="","",(30-IF($E47="",30,$E47))/60) | H47: =IF($C47="",0,IF(IFERROR(VLOOKUP($C47,Setup!$A$2:$B$60,2,FALSE),"N")="Y",$F47,0)) | I47: =IF($C47="",0,IF(IFERROR(VLOOKUP($C47,Setup!$A$2:$B$60,2,FALSE),"N")="Y",N($D47),0)) | J47: =IF($H47>0,$I47/$H47,"") | K47: =IF($F65>0,9,0)
A48: 46298 | B48: 23:30–00:00 | F48: =IF($C48="","",IF($E48="",30,$E48)/60) | G48: =IF($C48="","",(30-IF($E48="",30,$E48))/60) | H48: =IF($C48="",0,IF(IFERROR(VLOOKUP($C48,Setup!$A$2:$B$60,2,FALSE),"N")="Y",$F48,0)) | I48: =IF($C48="",0,IF(IFERROR(VLOOKUP($C48,Setup!$A$2:$B$60,2,FALSE),"N")="Y",N($D48),0)) | J48: =IF($H48>0,$I48/$H48,"")
A49: 46298 | B49: 00:00–00:30 | F49: =IF($C49="","",IF($E49="",30,$E49)/60) | G49: =IF($C49="","",(30-IF($E49="",30,$E49))/60) | H49: =IF($C49="",0,IF(IFERROR(VLOOKUP($C49,Setup!$A$2:$B$60,2,FALSE),"N")="Y",$F49,0)) | I49: =IF($C49="",0,IF(IFERROR(VLOOKUP($C49,Setup!$A$2:$B$60,2,FALSE),"N")="Y",N($D49),0)) | J49: =IF($H49>0,$I49/$H49,"")
A50: 46298 | B50: 00:30–01:00 | F50: =IF($C50="","",IF($E50="",30,$E50)/60) | G50: =IF($C50="","",(30-IF($E50="",30,$E50))/60) | H50: =IF($C50="",0,IF(IFERROR(VLOOKUP($C50,Setup!$A$2:$B$60,2,FALSE),"N")="Y",$F50,0)) | I50: =IF($C50="",0,IF(IFERROR(VLOOKUP($C50,Setup!$A$2:$B$60,2,FALSE),"N")="Y",N($D50),0)) | J50: =IF($H50>0,$I50/$H50,"")
...

Sheet Setup
A1: TAG | B1: PRODUCTIVE (Y/N) | C1: QUOTA / HR | E1: HOW THIS WORKBOOK WORKS
A2: SV | B2: Y | C2: 200 | E2: Accent headers are inputs you type into. Dim headers are formulas — leave them alone.
A3: CM | B3: Y | C3: 3000 | E3: Setup: mark a tag Y to make it a task. It counts toward tickets/hr and can carry a quota per hour.
A4: New tag 1 | B4: N | E4: Daily: one interval table per day. Pick a tag from the dropdown on each row, then type tickets and MINUTES WORKED.
A5: New tag 2 | B5: N | E5: Leave minutes blank for the full interval. HOURS, DEDUCTED, PROD HRS, TICKETS and T/HR are formulas.
A6: New tag 3 | B6: N | E6: Each day closes with its own TOTAL row. Summary reads whatever falls between its FROM / TO from Daily.
E7: New tags go in the blank rows under the tag list on this sheet. To log more days, re-export with a wider range.
